Workbook

Sheet TI036 Summary
B1: =TEXT(B2,"ddd") -> Thu | C1: =TEXT(C2,"ddd") -> Fri | D1: =TEXT(D2,"ddd") -> Sat | E1: =TEXT(E2,"ddd") -> Thu | F1: =TEXT(F2,"ddd") -> Fri | G1: =TEXT(G2,"ddd") -> Sat | H1: =TEXT(H2,"ddd") -> Mon | I1: =TEXT(I2,"ddd") -> Tue | ... Y1: =TEXT(Y2,"ddd") -> Sat | Z1: Sun-Mon | AA1: =TEXT(AA2,"ddd") -> Tue | AB1: =TEXT(AB2,"ddd") -> Wed | AC1: =TEXT(AC2,"ddd") -> Thu | AD1: =TEXT(AD2,"ddd") -> Fri | AE1: =TEXT(AE2,"ddd") -> Sat | AF1: =TEXT(AF2,"ddd") -> Mon | AG1: =TEXT(AG2,"ddd") -> Tue | AH1: =TEXT(AH2,"ddd") -> Wed | ... BC1: =TEXT(BC2,"ddd") -> Thu
B2: 46065 | C2: 46066 | D2: 46067 | E2: 46072 | F2: 46073 | G2: 46074 | H2: 46076 | I2: 46077 | J2: 46078 | K2: 46079 | L2: 46080 | M2: 46081 | N2: 46083 | O2: 46084 | P2: 46085 | Q2: 46086 | R2: 46087 | S2: 46088 | T2: 46090 | U2: 46091 | V2: 46092 | W2: 46093 | X2: 46094 | Y2: 46095 | Z2: 2026/3/15-16 | AA2: 46098 | AB2: 46099 | AC2: 46100 | AD2: 46101 | AE2: 46102 | AF2: 46104 | AG2: 46105 | AH2: 46106 | AI2: 46107 | AJ2: 46108 | AK2: 46109 | AL2: 46111 | AM2: 46112 | AN2: 46113 | AO2: 46114 | AP2: 46115 | AQ2: 46119 | AR2: 46120 | AS2: 46121 | AT2: 46122 | AU2: 46125 | AV2: 46126 | AW2: 46127 | AX2: 46128 | AY2: 46129 | AZ2: 46132 | BA2: 46133 | BB2: 46134 | BC2: 46135
A3: New Input Q'ty | B3: 4 | C3: 1 | D3: 1 | E3: 0 | F3: 0 | G3: 0 | H3: 0 | I3: 0 | J3: 0 | K3: 0 | L3: 0 | M3: 2 | N3: 12 | O3: 17 | P3: 14 | Q3: 18 | R3: 20 | S3: 21 | T3: 20 | U3: 16 | V3: 19 | W3: 17 | X3: 20 | Y3: 18 | Z3: 30 | AA3: 17 | AB3: 11 | AC3: 7 | AD3: 15 | AE3: 9 | AF3: 13 | AG3: 16 | AH3: 18 | AI3: 14 | AJ3: 15 | AK3: 18 | AL3: 29 | AM3: 20 | AN3: 18 | AO3: 20 | AP3: 20 | AQ3: 32 | AR3: 21 | AS3: 3 | AT3: 5 | AU3: 2 | AV3: 1 | AW3: 0 | AX3: 1 | AY3: 0 | AZ3: 1 | BA3: 0 | BB3: 0 | BC3: 0
A4: Pass Q'ty | B4: 4 | C4: 0 | D4: 0 | E4: 0 | F4: 0 | G4: 0 | H4: 0 | I4: 1 | J4: 0 | K4: 1 | L4: 0 | M4: 0 | N4: 9 | O4: 16 | P4: 18 | Q4: 5 | R4: 3 | S4: 18 | T4: 18 | U4: 11 | V4: 18 | W4: 19 | X4: 19 | Y4: 19 | Z4: 37 | AA4: 18 | AB4: 17 | AC4: 17 | AD4: 14 | AE4: 8 | AF4: 13 | AG4: 18 | AH4: 13 | AI4: 7 | AJ4: 18 | AK4: 16 | AL4: 28 | AM4: 18 | AN4: 19 | AO4: 19 | AP4: 15 | AQ4: 50 | AR4: 12 | AS4: 9 | AT4: 14 | AU4: 8 | AV4: 4 | AW4: 1 | AX4: 1 | AY4: 0 | AZ4: 1 | BA4: 1 | BB4: 0 | BC4: 0
A5: Running Q'ty | B5: 0 | C5: =B6+C3-C4-C6 -> 0 | D5: =C6+D3-D4-D6 -> 0 | E5: =D6+E3-E4-E6 -> 0 | F5: =E6+F3-F4-F6 -> 0 | G5: =F6+G3-G4-G6 -> 0 | H5: =G6+H3-H4-H6 -> 0 | I5: =H6+I3-I4-I6 -> 0 | J5: =I6+J3-J4-J6 -> 0 | ... M5: =L6+M3-M4-M6 -> 0 | N5: 0 | O5: 0 | P5: 0 | Q5: 0 | R5: 0 | S5: 0 | T5: 0 | U5: 0 | V5: 0 | W5: 0 | X5: 0 | Y5: 0 | Z5: 0 | AA5: 0 | AB5: 0 | AC5: 0 | AD5: 0 | AE5: 0 | AF5: 0 | AG5: 0 | AH5: 0 | AI5: 0 | AJ5: 0 | AK5: 0 | AL5: 0 | AM5: 0 | AN5: 0 | AO5: 0 | AP5: 0 | AQ5: 0 | AR5: 0 | AS5: 0 | AT5: 0 | AU5: 0 | AV5: 0 | AW5: 2 | AX5: 2 | AY5: 2 | AZ5: 1 | BA5: 0 | BB5: =BA6+BB3-BB4 -> 0 | BC5: =BB6+BC3-BC4 -> 0
A6: Failed Q'ty | B6: 0 | C6: 1 | D6: 2 | E6: 2 | F6: 2 | G6: 2 | H6: 2 | I6: 1 | J6: 1 | K6: 0 | L6: 0 | M6: 2 | N6: 5 | O6: 6 | P6: 2 | Q6: 15 | R6: 32 | S6: 35 | T6: 37 | U6: 42 | V6: 43 | W6: 41 | X6: 42 | Y6: 41 | Z6: 34 | AA6: 33 | AB6: 27 | AC6: 17 | AD6: 18 | AE6: 19 | AF6: 19 | AG6: 17 | AH6: 22 | AI6: 29 | AJ6: 26 | AK6: 28 | AL6: 29 | AM6: 31 | AN6: 30 | AO6: 31 | AP6: 36 | AQ6: 32 | AR6: 21 | AS6: 11 | AT6: 2 | AU6: 2 | AV6: 1 | AW6: 0 | AX6: 0 | AY6: 0 | AZ6: 0 | BA6: 0 | BB6: 0 | BC6: 0
A7: Untested / Insufficient test Q'ty | B7: 4 | C7: 0 | D7: 0 | E7: 0 | F7: 0 | G7: 0 | H7: 0 | I7: 0 | J7: 2 | K7: 0 | L7: 0 | M7: 0 | N7: 7 | O7: 16 | P7: 17 | Q7: 0 | R7: 0 | S7: 0 | T7: 0 | U7: 0 | V7: 8 | W7: 8 | X7: 0 | Y7: 0 | Z7: 0 | AA7: 0 | AB7: 0 | AC7: 0 | AD7: 0 | AE7: 0 | AF7: 0 | AG7: 0 | AH7: 5 | AI7: 0 | AJ7: 0 | AK7: 0 | AL7: 0 | AM7: 0 | AN7: 0 | AO7: 0 | AP7: 0 | AQ7: 0 | AR7: 0 | AS7: 0 | AT7: 0 | AU7: 0 | AV7: 0 | AW7: 0 | AX7: 0 | AY7: 0 | AZ7: 0 | BA7: 0 | BB7: 0 | BC7: 0
A8: L11 Finished Goods CUMULATIVE | B8: 4 | C8: =B8+C4 -> 4 | D8: =C8+D4 -> 4 | E8: =D8+E4 -> 4 | F8: =E8+F4 -> 4 | G8: =F8+G4 -> 4 | H8: =G8+H4 -> 4 | I8: =H8+I4 -> 5 | J8: =I8+J4 -> 5 | ... BC8: =BB8+BC4 -> 575
A9: Yield Rate | B9: =IFERROR((B4-B7)/(B4+B6),"N/a") -> 0 | C9: =IFERROR((C4-C7)/(C4+C6),"N/a") -> 0 | D9: =IFERROR((D4-D7)/(D4+D6),"N/a") -> 0 | E9: =IFERROR((E4-E7)/(E4+E6),"N/a") -> 0 | F9: =IFERROR((F4-F7)/(F4+F6),"N/a") -> 0 | G9: =IFERROR((G4-G7)/(G4+G6),"N/a") -> 0 | H9: =IFERROR((H4-H7)/(H4+H6),"N/a") -> 0 | I9: =IFERROR((I4-I7)/(I4+I6),"N/a") -> 0.5 | ... K9: =IFERROR((K4-K7)/(K4+K6),"N/a") -> 1 | L9: =IFERROR((L4-L7)/(L4+L6),"N/A") -> N/A | M9: =IFERROR((M4-M7)/(M4+M6),"N/a") -> 0 | N9: =IFERROR((N4-N7)/(N4+N6),"N/a") -> 0.14285714 | O9: =IFERROR((O4-O7)/(O4+O6),"N/a") -> 0 | P9: =IFERROR((P4-P7)/(P4+P6),"N/a") -> 0.05 | Q9: =IFERROR((Q4-Q7)/(Q4+Q6),"N/a") -> 0.25 | R9: =IFERROR((R4-R7)/(R4+R6),"N/a") -> 0.085714286 | S9: =IFERROR(S4/(S4+S6),"N/A") -> 0.33962264 | T9: =IFERROR(T4/(T4+T6),"N/A") -> 0.32727273 | U9: =IFERROR(U4/(U4+U6),"N/A") -> 0.20754717 | V9: =IFERROR(V4/(V4+V6),"N/A") -> 0.29508197 | W9: =IFERROR(W4/(W4+W6),"N/A") -> 0.31666667 | X9: =IFERROR(X4/(X4+X6),"N/A") -> 0.31147541 | Y9: =IFERROR(Y4/(Y4+Y6),"N/A") -> 0.31666667 | Z9: =IFERROR(Z4/(Z4+Z6),"N/A") -> 0.52112676 | ... BC9: =IFERROR(BC4/(BC4+BC6),"N/A") -> N/A

Sheet Component replacement Pareto
A4: Part Description | B4: Replace Component | C4: Fail Q'ty | D4: Weight %
A5: =VLOOKUP(B5,'PN Dictionary'!A:B,2,FALSE) -> GB300 L10 | B5: =PIVOT!A5 -> ARS-121GL-NB3-LC1-TD004 | C5: =PIVOT!B5 -> 2 | D5: =C5/$C$16 -> 0.66666667
A6: =VLOOKUP(B6,'PN Dictionary'!A:B,2,FALSE) -> Cable Cartridge | B6: =PIVOT!A6 -> SSE-NVL72-CC | C6: =PIVOT!B6 -> 1 | D6: =C6/$C$16 -> 0.33333333
B7: Total | C7: =PIVOT!B7 -> 3 | D7: =C7/$C$16 -> 1
A8: =VLOOKUP(B8,'PN Dictionary'!A:B,2,FALSE) -> #N/A | B8: =PIVOT!A8 -> 0 | C8: =PIVOT!B8 -> 0 | D8: =C8/$C$16 -> 0
A9: =VLOOKUP(B9,'PN Dictionary'!A:B,2,FALSE) -> #N/A | B9: =PIVOT!A9 -> 0 | C9: =PIVOT!B9 -> 0 | D9: =C9/$C$16 -> 0
A10: =VLOOKUP(B10,'PN Dictionary'!A:B,2,FALSE) -> #N/A | B10: =PIVOT!A10 -> 0 | C10: =PIVOT!B10 -> 0 | D10: =C10/$C$16 -> 0
A11: =VLOOKUP(B11,'PN Dictionary'!A:B,2,FALSE) -> #N/A | B11: =PIVOT!A11 -> 0 | C11: =PIVOT!B11 -> 0 | D11: =C11/$C$16 -> 0
A12: =VLOOKUP(B12,'PN Dictionary'!A:B,2,FALSE) -> #N/A | B12: =PIVOT!A12 -> 0 | C12: =PIVOT!B12 -> 0 | D12: =C12/$C$16 -> 0
B13: Total | C13: =PIVOT!B13 -> 0 | D13: =C13/$C$16 -> 0
A14: =VLOOKUP(B14,'PN Dictionary'!A:B,2,FALSE) -> #N/A | B14: =PIVOT!A14 -> 0 | C14: =PIVOT!B14 -> 0 | D14: =C14/$C$16 -> 0
D15: =C15/$C$16 -> 0
B16: Total | C16: 3 | D16: =C16/$C$16 -> 1
A36: Part Description | B36: Replace Component | C36: Fail Q'ty | D36: Weight %
A37: =VLOOKUP(B37,'PN Dictionary'!A:B,2,FALSE) -> GB300 L10 | B37: =PIVOT!E5 -> PIO-121GL-NB3-LC5-TI036 | C37: =PIVOT!F5 -> 332 | D37: =C37/$C$48 -> 0.7597254
A38: =VLOOKUP(B38,'PN Dictionary'!A:B,2,FALSE) -> Cable Cartridge | B38: =PIVOT!E6 -> SSE-NVL72-CC | C38: =PIVOT!F6 -> 54 | D38: =C38/$C$48 -> 0.12356979
A39: =VLOOKUP(B39,'PN Dictionary'!A:B,2,FALSE) -> NVSwitch | B39: =PIVOT!E7 -> SSE-NVL72SW-N5500 | C39: =PIVOT!F7 -> 35 | D39: =C39/$C$48 -> 0.080091533
A40: =VLOOKUP(B40,'PN Dictionary'!A:B,2,FALSE) -> power shelf left input | B40: =PIVOT!E8 -> SRK-01LNPF-33B1-01 | C40: =PIVOT!F8 -> 6 | D40: =C40/$C$48 -> 0.013729977
A41: =VLOOKUP(B41,'PN Dictionary'!A:B,2,FALSE) -> Power shelf control module | B41: =PIVOT!E9 -> SRK-01LNPM-PMB1-01-TI036 | C41: =PIVOT!F9 -> 5 | D41: =C41/$C$48 -> 0.011441648
A42: =VLOOKUP(B42,'PN Dictionary'!A:B,2,FALSE) -> 5.5kW PSU GB300 | B42: =PIVOT!E10 -> SRK-01LNPW-5KB1-01-TI036 | C42: =PIVOT!F10 -> 4 | D42: =C42/$C$48 -> 0.0091533181
A43: =VLOOKUP(B43,'PN Dictionary'!A:B,2,FALSE) -> LiteOn Power Shelf Right Input | B43: =PIVOT!E11 -> SRK-01LNPF-33B1R-01 | C43: =PIVOT!F11 -> 1 | D43: =C43/$C$48 -> 0.0022883295
B44: Total | C44: 437
B48: Total | C48: 437 | D48: =SUM(D37:D43) -> 1
A62: Part Description | B62: Replace Component | C62: Fail Q'ty | D62: Weight %
A63: =VLOOKUP(B63,'PN Dictionary'!A:B,2,FALSE) -> #REF! | B63: =#REF! -> #REF! | C63: =#REF! -> #REF! | D63: =C63/$C$48 -> #REF!
A64: =VLOOKUP(B64,'PN Dictionary'!A:B,2,FALSE) -> #REF! | B64: =#REF! -> #REF! | C64: =#REF! -> #REF! | D64: =C64/$C$48 -> #REF!
A65: =VLOOKUP(B65,'PN Dictionary'!A:B,2,FALSE) -> #REF! | B65: =#REF! -> #REF! | C65: =#REF! -> #REF! | D65: =C65/$C$48 -> #REF!
A66: =VLOOKUP(B66,'PN Dictionary'!A:B,2,FALSE) -> #REF! | B66: =#REF! -> #REF! | C66: =#REF! -> #REF! | D66: =C66/$C$48 -> #REF!
A67: =VLOOKUP(B67,'PN Dictionary'!A:B,2,FALSE) -> #REF! | B67: =#REF! -> #REF! | C67: =#REF! -> #REF! | D67: =C67/$C$48 -> #REF!
A68: =VLOOKUP(B68,'PN Dictionary'!A:B,2,FALSE) -> #REF! | B68: =#REF! -> #REF! | C68: =#REF! -> #REF! | D68: =C68/$C$48 -> #REF!
A69: =VLOOKUP(B69,'PN Dictionary'!A:B,2,FALSE) -> #REF! | B69: =#REF! -> #REF! | C69: =#REF! -> #REF! | D69: =C69/$C$48 -> #REF!
B74: Total | C74: =SUM(C63:C73) -> #REF! | D74: =SUM(D63:D73) -> #REF!

Sheet PIVOT
A1: Rack P/N | B1: SRS-GB300-M1-TD004 | E1: Rack P/N | F1: SRS-52UGB300-NVL72-TI036 | I1: Rack P/N | J1: SRS-GB300-NVL72-M0-FG001
A2: Action | B2: REPLACE | E2: Action | F2: REPLACE | I2: Action | J2: REPLACE
A4: 列標籤 | B4: 計數 - Defect P/N | E4: 列標籤 | F4: 計數 - Defect P/N | I4: 列標籤 | J4: 計數 - Defect P/N
A5: ARS-121GL-NB3-LC1-TD004 | B5: 2 | E5: PIO-121GL-NB3-LC5-TI036 | F5: 332 | I5: ARS-121GL-NB3-LCC-FG001 | J5: 96
A6: SSE-NVL72-CC | B6: 1 | E6: SSE-NVL72-CC | F6: 54 | I6: SSE-NVL72-CC | J6: 56
A7: 總計 | B7: 3 | E7: SSE-NVL72SW-N5500 | F7: 35 | I7: SSE-NVL72SW-N5500 | J7: 19
E8: SRK-01LNPF-33B1-01 | F8: 6 | I8: SRK-01DTPM-PMB1-01 | J8: 10
E9: SRK-01LNPM-PMB1-01-TI036 | F9: 5 | I9: SRK-01DTPF-33B1-01 | J9: 8
E10: SRK-01LNPW-5KB1-01-TI036 | F10: 4 | I10: SRK-01DTPF-33B1R-01 | J10: 6
E11: SRK-01LNPF-33B1R-01 | F11: 1 | I11: PIO-121GL-NB3-LC5-TI036 | J11: 1
E12: 總計 | F12: 437 | I12: SRK-44IXSE-66KW-MGX-A1 | J12: 1
I13: 總計 | J13: 197

Sheet Fail Information
A1: Failure ID | B1: Fix Date | C1: Rack P/N | D1: Rack S/N | E1: Error Code | F1: Error Description | G1: Error Date | H1: Action | I1: FAIL Issue | J1: Description | K1: Defect P/N | L1: Defect Part S/N | M1: New Part S/N | N1: Form Factor | O1: Production Line | P1: Fail By | Q1: Fail Stage
A2: P25A03262 | B2: 10/29/2025 7:38:56 AM | C2: SRS-GB300-NVL72-M4-TW008 | D2: SR021027259879 | E2: PS015 | G2: 10/29/2025 | H2: REPLACE | I2: 第6個 power BMC 卡 LED異常 和 速率異常100M/S_TW3600_更換power BMC 卡 | J2: =VLOOKUP(K2,'PN Dictionary'!A:B,2,FALSE) -> Power Shelf Control Module | K2: SRK-01DTPM-PMB1-01 | L2: SV25380359 | M2: SV25380370 | N2: Rack | O2: TWSPLG | P2: 3600 | Q2: InTest
A3: P25A03291 | B3: 10/29/2025 9:44:05 AM | C3: SRS-GB300-NVL72-M4-TW008 | D3: SR021028251215 | E3: RK111 | G3: 10/29/2025 | H3: REPLACE | I3: 第10台 單機 可正常開機 無法連線 且 遠端BMC連線無效_TW3600_更換單機 | J3: =VLOOKUP(K3,'PN Dictionary'!A:B,2,FALSE) -> GB300 L10 | K3: PIO-121GL-NB3-LC5-TW008 | L3: A968459X5A08915 | M3: A968459X5A10392 | N3: Rack | O3: TWSPLG | P3: 3600 | Q3: InTest
A4: P25A03454 | B4: 10/30/2025 12:08:15 AM | C4: SRS-GB300-NVL72-M4-TW008 | D4: SR021028251215 | E4: RK205 | G4: 10/30/2025 | H4: REPLACE | I4: GPU not detected 0009:06.00.0 | J4: =VLOOKUP(K4,'PN Dictionary'!A:B,2,FALSE) -> GB300 L10 | K4: PIO-121GL-NB3-LC5-TW008 | L4: A968459X5A10392 | M4: A968459X5A09028 | N4: Rack | O4: TWSPLG | P4: 1348 | Q4: InTest
A5: P25B00136 | B5: 11/1/2025 9:29:43 PM | C5: SRS-GB300-NVL72-M4-TW008 | D5: SR021030259476 | E5: RK205 | G5: 11/1/2025 | H5: REPLACE | I5: NVIDIA SMI tool only detected 3 GPU and it does not match the requesed 4 | J5: =VLOOKUP(K5,'PN Dictionary'!A:B,2,FALSE) -> GB300 L10 | K5: PIO-121GL-NB3-LC5-TW008 | L5: A968459X5A10400 | M5: A968459X5A09026 | N5: Rack | O5: TWSPLG | P5: 1348 | Q5: InTest
A6: P25B00140 | B6: 11/1/2025 10:32:17 PM | C6: SRS-GB300-NVL72-M4-TW008 | D6: SR021101259934 | E6: RK099 | G6: 11/1/2025 | H6: REPLACE | I6: 不開機 | J6: =VLOOKUP(K6,'PN Dictionary'!A:B,2,FALSE) -> GB300 L10 | K6: PIO-121GL-NB3-LC5-TW008 | L6: A968459X5A10455 | M6: A968459X5A10394 | N6: Rack | O6: TWSPLG | P6: 1348 | Q6: InTest
A7: P25B00141 | B7: 11/1/2025 10:35:07 PM | C7: SRS-GB300-NVL72-M4-TW008 | D7: SR021101259934 | E7: RK099 | G7: 11/1/2025 | H7: REPLACE | I7: power燈不亮 | J7: =VLOOKUP(K7,'PN Dictionary'!A:B,2,FALSE) -> GB300 L10 | K7: PIO-121GL-NB3-LC5-TW008 | L7: A968459X5A11343 | M7: A968459X5A11327 | N7: Rack | O7: TWSPLG | P7: 1348 | Q7: InTest
A8: P25B00144 | B8: 11/1/2025 10:41:30 PM | C8: SRS-GB300-NVL72-M4-TW008 | D8: SR021030256516 | E8: RK099 | G8: 11/1/2025 | H8: REPLACE | I8: 機箱不良 左後方 | J8: =VLOOKUP(K8,'PN Dictionary'!A:B,2,FALSE) -> GB300 L10 | K8: PIO-121GL-NB3-LC5-TW008 | L8: A968459X5A09462 | M8: A968459X5A09031 | N8: Rack | O8: TWSPLG | P8: 1348 | Q8: InTest
A9: P25B00156 | B9: 11/2/2025 12:55:18 AM | C9: SRS-GB300-NVL72-M4-TW008 | D9: SR021101253206 | E9: MB002 | G9: 11/2/2025 | H9: REPLACE | I9: DOA - Unable to power on (無法開機,無電源) | J9: =VLOOKUP(K9,'PN Dictionary'!A:B,2,FALSE) -> GB300 L10 | K9: PIO-121GL-NB3-LC5-TW008 | L9: A968459X5A09672 | M9: A968459X5A08946 | N9: Rack | O9: TWSPLG | P9: 1348 | Q9: InTest
A10: P25B00159 | B10: 11/2/2025 1:25:16 AM | C10: SRS-GB300-NVL72-M4-TW008 | D10: SR021101259934 | E10: RK205 | G10: 11/2/2025 | H10: REPLACE | I10: Cannot power by power button and WebGUI. Power On failed log in SEL | J10: =VLOOKUP(K10,'PN Dictionary'!A:B,2,FALSE) -> GB300 L10 | K10: PIO-121GL-NB3-LC5-TW008 | L10: A968459X5A10402 | M10: A968459X5A10437 | N10: Rack | O10: TWSPLG | P10: 1348 | Q10: InTest
A11: P25B00163 | B11: 11/2/2025 1:58:29 AM | C11: SRS-GB300-NVL72-M4-TW008 | D11: SR021101259934 | E11: RK205 | G11: 11/2/2025 | H11: REPLACE | I11: Chassis_0_LeakDetector_0_ColdPlate' reading of 0.000000 (Volts) is below the 1.300000 lower critical | J11: =VLOOKUP(K11,'PN Dictionary'!A:B,2,FALSE) -> GB300 L10 | K11: PIO-121GL-NB3-LC5-TW008 | L11: A968459X5A11341 | M11: A968459X5A10386 | N11: Rack | O11: TWSPLG | P11: 1348 | Q11: InTest
A12: P25B00190 | B12: 11/3/2025 12:46:18 PM | C12: SRS-GB300-NVL72-M4-TW008 | D12: SR021101254955 | E12: RK098 | G12: 11/3/2025 | H12: REPLACE | I12: 不開機_TW640_更換單機 | J12: =VLOOKUP(K12,'PN Dictionary'!A:B,2,FALSE) -> GB300 L10 | K12: PIO-121GL-NB3-LC5-TW008 | L12: A968459X5A10446 | M12: A968459X5A10562 | N12: Rack | O12: TWSPLG | P12: 3600 | Q12: InTest
A13: P25B00195 | B13: 11/3/2025 2:30:39 PM | C13: SRS-GB300-NVL72-M4-TW008 | D13: SR021030256516 | E13: RK110 | G13: 11/3/2025 | H13: REPLACE | I13: COMPUTE_NODE_8 NVRM invalid state or config @(Rack slot 18, CBC 2, 4x19 connector 2) [link_downed error value of 1 exceeded threshold of 0 on (0009:06:00.0_SN_1763925822295, nvlink 1)] @(Rack slot 18, CBC 1, 4x19 connector 1, column 18, pins A/B, G/H, C/D, E/F) PEER (Rack slot 9, CBC 1, 8x10 connector 1, column 1, pins C/D, G/H, A/B, E/F, port acp105)_TW3600_更換單機 | J13: =VLOOKUP(K13,'PN Dictionary'!A:B,2,FALSE) -> GB300 L10 | K13: PIO-121GL-NB3-LC5-TW008 | L13: A968459X5A08922 | M13: A968459X5A09029 | N13: Rack | O13: TWSPLG | P13: 3600 | Q13: InTest
A14: P25B00256 | B14: 11/3/2025 8:47:36 PM | C14: SRS-GB300-NVL72-M4-TW008 | D14: SR021101253206 | E14: RK024 | G14: 11/3/2025 | H14: FIX | I14: Cable Cartridge L11 FD Test [FAIL] | J14: =VLOOKUP(K14,'PN Dictionary'!A:B,2,FALSE) -> GB300 L10 | K14: PIO-121GL-NB3-LC5-TW008 | L14: A968459X5A08966 | N14: Rack | O14: TWSPLG | P14: 90131 | Q14: InBurnin
A15: P25B00351 | B15: 11/4/2025 11:59:20 AM | C15: SRS-GB300-NVL72-M4-TW008 | D15: SR021101254955 | E15: RK205 | G15: 11/4/2025 | H15: REPLACE | I15: Rack0_SW2_acp93 CC0_C5_Lane_5 link_none_TW3600_更換NVLSwitch | J15: =VLOOKUP(K15,'PN Dictionary'!A:B,2,FALSE) -> NVSwitch | K15: SSE-NVL72SW-N5500 | L15: MT2529605BGB | M15: MT25336014ZG | N15: Rack | O15: TWSPLG | P15: 3600 | Q15: InTest
A16: P25B00358 | B16: 11/4/2025 12:55:35 PM | C16: SRS-GB300-NVL72-M4-TW008 | D16: SR021030253812 | E16: RK024 | G16: 11/4/2025 | H16: REPLACE | I16: Rack0_SW7_acp8 CC3_C1_Lane_14 link_bad_quality_TW3600_更換Cable cartridge | J16: =VLOOKUP(K16,'PN Dictionary'!A:B,2,FALSE) -> Cable Cartridge | K16: SSE-NVL72-CC | L16: 1823425350328 | M16: 1823225356627 | N16: Rack | O16: TWSPLG | P16: 3600 | Q16: InTest
A17: P25B00416 | B17: 11/5/2025 12:50:59 AM | C17: SRS-GB300-NVL72-M4-TW008 | D17: SR021103256952 | E17: RK024 | G17: 11/5/2025 | H17: REPLACE | I17: 位置:http://10.160.100.12/logs/xAI/2025/November/SR021103256952/04/R-BURN/A968459X5A10427/7CC255910DE3/ | J17: =VLOOKUP(K17,'PN Dictionary'!A:B,2,FALSE) -> Cable Cartridge | K17: SSE-NVL72-CC | L17: 1823325351260 | M17: 1823225356593 | N17: Rack | O17: TWSPLG | P17: 1348 | Q17: InTest
A18: P25B00460 | B18: 11/5/2025 10:11:14 AM | C18: SRS-GB300-NVL72-M4-TW008 | D18: SR021103252664 | E18: RK098 | G18: 11/5/2025 | H18: REPLACE | I18: 有過電 無法開機 (STBY_POWER_PG-I failed to assert after 20.0 seconds. Disabling STBY_POWER_EN)_TW3600_更換單機 | J18: =VLOOKUP(K18,'PN Dictionary'!A:B,2,FALSE) -> GB300 L10 | K18: PIO-121GL-NB3-LC5-TW008 | L18: A968459X5B00026 | M18: A968459X5B00470 | N18: Rack | O18: TWSPLG | P18: 3600 | Q18: InTest
A19: P25B00474 | B19: 11/5/2025 1:03:18 PM | C19: SRS-GB300-NVL72-M4-TW008 | D19: SR021030259476 | E19: RK024 | G19: 11/5/2025 | H19: REPLACE | I19: switch_tray,Rack0_SW0_acp64,CC3_C15_Lane_0, link_none,0_TW3600_更換CC3 | J19: =VLOOKUP(K19,'PN Dictionary'!A:B,2,FALSE) -> Cable Cartridge | K19: SSE-NVL72-CC | L19: 1823425350158 | M19: 2023825882527 | N19: Rack | O19: TWSPLG | P19: 3600 | Q19: InTest
A20: P25B00545 | B20: 11/5/2025 8:11:33 PM | C20: SRS-GB300-NVL72-M4-TW008 | D20: SR021103252664 | E20: RK098 | G20: 11/5/2025 | H20: REPLACE | I20: Use to replace L10 servers that have failed Rburn test from the rack. (更換Rack Rburn test fail的 L10系統) | J20: =VLOOKUP(K20,'PN Dictionary'!A:B,2,FALSE) -> GB300 L10 | K20: PIO-121GL-NB3-LC5-TW008 | L20: A968459X5B00022 | M20: A968459X5B00253 | N20: Rack | O20: TWSPLG | P20: 1348 | Q20: InTest
A21: P25B00546 | B21: 11/5/2025 8:13:57 PM | C21: SRS-GB300-NVL72-M4-TW008 | D21: SR021103253681 | E21: RK098 | G21: 11/5/2025 | H21: REPLACE | I21: Use to replace L10 servers that have failed Rburn test from the rack. (更換Rack Rburn test fail的 L10系統) | J21: =VLOOKUP(K21,'PN Dictionary'!A:B,2,FALSE) -> GB300 L10 | K21: PIO-121GL-NB3-LC5-TW008 | L21: A968459X5B00101 | M21: A968459X5B00050 | N21: Rack | O21: TWSPLG | P21: 1348 | Q21: InTest
A22: P25B00755 | B22: 11/7/2025 2:44:39 AM | C22: SRS-GB300-NVL72-M4-TW008 | D22: SR021105256796 | E22: RK098 | G22: 11/7/2025 | H22: REPLACE | I22: Use to replace L10 servers that have failed Rburn test from the rack. (更換Rack Rburn test fail的 L10系統) | J22: =VLOOKUP(K22,'PN Dictionary'!A:B,2,FALSE) -> GB300 L10 | K22: PIO-121GL-NB3-LC5-TW008 | L22: A968459X5A10402 | M22: A968459X5A10580 | N22: Rack | O22: TWSPLG | P22: 1348 | Q22: InTest
A23: P25B00756 | B23: 11/7/2025 2:45:49 AM | C23: SRS-GB300-NVL72-M4-TW008 | D23: SR021105256796 | E23: RK098 | G23: 11/7/2025 | H23: REPLACE | I23: Use to replace L10 servers that have failed Rburn test from the rack. (更換Rack Rburn test fail的 L10系統) | J23: =VLOOKUP(K23,'PN Dictionary'!A:B,2,FALSE) -> GB300 L10 | K23: PIO-121GL-NB3-LC5-TW008 | L23: A968459X5A10446 | M23: A968459X5A08963 | N23: Rack | O23: TWSPLG | P23: 1348 | Q23: InTest
A24: P25B00765 | B24: 11/7/2025 1:46:10 PM | C24: SRS-GB300-NVL72-M4-TW008 | D24: SR021105256796 | E24: RK110 | G24: 11/7/2025 | H24: REPLACE | I24: Sensor 'Chassis_0_LeakDetector_0_ColdPlate' reading of 0.000000 (Volts) is below the 1.300000 lower critical threshold._TW3600_更換單機 | J24: =VLOOKUP(K24,'PN Dictionary'!A:B,2,FALSE) -> GB300 L10 | K24: PIO-121GL-NB3-LC5-TW008 | L24: A968459X5A10584 | M24: A968459X5A09431 | N24: Rack | O24: TWSPLG | P24: 3600 | Q24: InTest
A25: P25B00845 | B25: 11/7/2025 3:09:17 PM | C25: SRS-GB300-NVL72-M4-TW008 | D25: SR021105256796 | E25: RK205 | G25: 11/7/2025 | H25: REPLACE | I25: COMPUTE_NODE_15 | DGX-000000000125 | CableCartridgeEepromCheck | cable_cartridge | | GPU | | Error while invoking api /redfish/v1/Chassis/CBC_2. Error message => The requested resource of type Chassis named 'CBC_2' was not found._TW3600_更換單機 | J25: =VLOOKUP(K25,'PN Dictionary'!A:B,2,FALSE) -> GB300 L10 | K25: PIO-121GL-NB3-LC5-TW008 | L25: A968459X5A08966 | M25: A968459X5A08925 | N25: Rack | O25: TWSPLG | P25: 3600 | Q25: InTest
A26: P25B00869 | B26: 11/7/2025 6:26:51 PM | C26: SRS-GB300-NVL72-M4-TW008 | D26: SR021105259364 | E26: RK024 | G26: 11/7/2025 | H26: REPLACE | I26: NVLINK SLOT5 BENT PIN | J26: =VLOOKUP(K26,'PN Dictionary'!A:B,2,FALSE) -> Cable Cartridge | K26: SSE-NVL72-CC | L26: 1823025355085 | M26: 1822825354542 | N26: Rack | O26: TWSPLG | P26: 1348 | Q26: InTest
A27: P25B00890 | B27: 11/7/2025 10:20:26 PM | C27: SRS-GB300-NVL72-M4-TW008 | D27: SR021106258634 | E27: RK098 | G27: 11/7/2025 | H27: REPLACE | I27: Use to replace L10 servers that have failed Rburn test from the rack. (更換Rack Rburn test fail的 L10系統) | J27: =VLOOKUP(K27,'PN Dictionary'!A:B,2,FALSE) -> GB300 L10 | K27: PIO-121GL-NB3-LC5-TW008 | L27: A968459X5A15670 | M27: A968459X5B00062 | N27: Rack | O27: TWSPLG | P27: 1348 | Q27: InTest
A28: P25B00952 | B28: 11/8/2025 10:10:52 PM | C28: SRS-GB300-NVL72-M4-TW008 | D28: SR021106255795 | E28: RK024 | G28: 11/8/2025 | H28: REPLACE | I28: Cable cartridge Defect | J28: =VLOOKUP(K28,'PN Dictionary'!A:B,2,FALSE) -> Cable Cartridge | K28: SSE-NVL72-CC | L28: 1822825355833 | M28: 1822825354176 | N28: Rack | O28: TWSPLG | P28: 1348 | Q28: InTest
A29: P25B00969 | B29: 11/9/2025 12:13:30 PM | C29: SRS-GB300-NVL72-M4-TW008 | D29: SR021106255139 | E29: RK024 | G29: 11/9/2025 | H29: REPLACE | I29: Rack0_SW8_acp73,CC0_C0_Lane_17, link_none (Bent Pin)_TW3600_更換CC0 | J29: =VLOOKUP(K29,'PN Dictionary'!A:B,2,FALSE) -> Cable Cartridge | K29: SSE-NVL72-CC | L29: 1822825356229 | M29: 1822825354109 | N29: Rack | O29: TWSPLG | P29: 3600 | Q29: InTest
A30: P25B00970 | B30: 11/9/2025 12:46:33 PM | C30: SRS-GB300-NVL72-M4-TW008 | D30: SR021106259634 | E30: RK205 | G30: 11/9/2025 | H30: REPLACE | I30: Rack0_SW0_acp47 CC2_C11_Lane_0 link_none_TW3600_更換單機 | J30: =VLOOKUP(K30,'PN Dictionary'!A:B,2,FALSE) -> GB300 L10 | K30: PIO-121GL-NB3-LC5-TW008 | L30: A968459X5B00392 | M30: A968459X5A15605 | N30: Rack | O30: TWSPLG | P30: 3600 | Q30: InTest
A31: P25B00971 | B31: 11/9/2025 12:49:02 PM | C31: SRS-GB300-NVL72-M4-TW008 | D31: SR021106252253 | E31: RK205 | G31: 11/9/2025 | H31: REPLACE | I31: COMPUTE_NODE_17 | DGX-000000000125 | CableCartridgeEepromCheck | cable_cartridge | | GPU | | Error while invoking api /redfish/v1/Chassis/CBC_2. Error message => The requested resource of type Chassis named 'CBC_2' was not found._TW3600_更換單機 | J31: =VLOOKUP(K31,'PN Dictionary'!A:B,2,FALSE) -> GB300 L10 | K31: PIO-121GL-NB3-LC5-TW008 | L31: A968459X5B01293 | M31: A968459X5A15604 | N31: Rack | O31: TWSPLG | P31: 3600 | Q31: InTest
A32: P25B00981 | B32: 11/9/2025 2:23:52 PM | C32: SRS-GB300-NVL72-M4-TW008 | D32: SR021106254604 | E32: RK107 | G32: 11/9/2025 | H32: REPLACE | I32: Sensor 'Chassis_0_LeakDetector_0_ColdPlate' reading of 1.285600 (Volts) is below the 1.300000 lower critical threshold_TW3600_更換單機 | J32: =VLOOKUP(K32,'PN Dictionary'!A:B,2,FALSE) -> GB300 L10 | K32: PIO-121GL-NB3-LC5-TW008 | L32: A968459X5B01450 | M32: A968459X5A15603 | N32: Rack | O32: TWSPLG | P32: 3600 | Q32: InTest
A33: P25B01078 | B33: 11/10/2025 1:17:33 PM | C33: SRS-GB300-NVL72-M4-TW008 | D33: SR021106251002 | E33: RK023 | G33: 11/10/2025 | H33: REPLACE | I33: 11/6 可正常更新成功 ，有IP 但無法連線_TW3600_更換NVLswitch | J33: =VLOOKUP(K33,'PN Dictionary'!A:B,2,FALSE) -> NVSwitch | K33: SSE-NVL72SW-N5500 | L33: MT2527605A8T | M33: MT253460006X | N33: Rack | O33: TWSPLG | P33: 3600 | Q33: InTest
A34: P25B01121 | B34: 11/10/2025 4:21:30 PM | C34: SRS-GB300-NVL72-M4-TW008 | D34: SR021106251049 | E34: RK023 | G34: 11/10/2025 | H34: REPLACE | I34: NVLINK Switch Functional Issue | J34: =VLOOKUP(K34,'PN Dictionary'!A:B,2,FALSE) -> NVSwitch | K34: SSE-NVL72SW-N5500 | L34: MT2527605A8T | M34: MT2532600FR7 | N34: Rack | O34: TWSPLG | P34: 1348 | Q34: InTest
A35: P25B01143 | B35: 11/10/2025 5:58:16 PM | C35: SRS-GB300-NVL72-M4-TW008 | D35: SR021106251049 | E35: RK022 | G35: 11/10/2025 | H35: REPLACE | I35: 無法更新 | J35: =VLOOKUP(K35,'PN Dictionary'!A:B,2,FALSE) -> Delta Power Shelf Left Input | K35: SRK-01DTPF-33B1-01 | L35: DGPST253700LQ | M35: DGPST253701GC | N35: Rack | O35: TWSPLG | P35: 1348 | Q35: InTest
A36: P25B01218 | B36: 11/12/2025 7:33:35 AM | C36: SRS-GB300-NVL72-M4-TW008 | D36: SR021110256854 | E36: RK205 | G36: 11/12/2025 | H36: REPLACE | I36: COMPUTE_NODE_10 | DGX-000000000126 | CableCartridgeEepromCheck | cable_cartridge | | GPU | | Got exit code 7 while executing ('curl', '--silent', '--insecure', '--user', 'smctest:Supermicro@123', 'https://10.100.30.11/redfish/v1/Chassis/CBC_0')_TW3600_更換單機 | J36: =VLOOKUP(K36,'PN Dictionary'!A:B,2,FALSE) -> GB300 L10 | K36: PIO-121GL-NB3-LC5-TW008 | L36: A968459X5B02275 | M36: A968459X5B02289 | N36: Rack | O36: TWSPLG | P36: 3600 | Q36: InTest
A37: P25B01268 | B37: 11/12/2025 8:26:46 AM | C37: SRS-GB300-NVL72-M4-TW008 | D37: SR021110256189 | E37: RK109 | G37: 11/12/2025 | H37: REPLACE | I37: power LED 異常黯淡_TW3600_更換單機 | J37: =VLOOKUP(K37,'PN Dictionary'!A:B,2,FALSE) -> GB300 L10 | K37: PIO-121GL-NB3-LC5-TW008 | L37: A968459X5B00421 | M37: A968459X5B02044 | N37: Rack | O37: TWSPLG | P37: 3600 | Q37: InTest
A38: P25B01291 | B38: 11/12/2025 10:00:39 AM | C38: SRS-GB300-NVL72-M4-TW008 | D38: SR021110256189 | E38: RK024 | G38: 11/12/2025 | H38: REPLACE | I38: Rack0_SW6_acp19,CC2_C4_Lane_12, link_none 大量CC2 FAIL_TW3600_更換CC2 | J38: =VLOOKUP(K38,'PN Dictionary'!A:B,2,FALSE) -> Cable Cartridge | K38: SSE-NVL72-CC | L38: 1823325351252 | M38: 1823325354730 | N38: Rack | O38: TWSPLG | P38: 3600 | Q38: InTest
A39: P25B01365 | B39: 11/12/2025 3:10:39 PM | C39: SRS-GB300-NVL72-M4-TW008 | D39: SR021110253703 | E39: RK098 | G39: 11/12/2025 | H39: REPLACE | I39: 開機一下後 自動關機_TW3600_更換單機 | J39: =VLOOKUP(K39,'PN Dictionary'!A:B,2,FALSE) -> GB300 L10 | K39: PIO-121GL-NB3-LC5-TW008 | L39: A968459X5B01928 | M39: A968459X5B00421 | N39: Rack | O39: TWSPLG | P39: 3600 | Q39: InTest
A40: P25B01432 | B40: 11/12/2025 10:47:12 PM | C40: SRS-GB300-NVL72-M4-TW008 | D40: SR021110253399 | E40: RK203 | G40: 11/12/2025 | H40: REPLACE | I40: control board 橘燈不亮 | J40: =VLOOKUP(K40,'PN Dictionary'!A:B,2,FALSE) -> Power Shelf Control Module | K40: SRK-01DTPM-PMB1-01 | L40: SV25380737 | M40: SV25380633 | N40: Rack | O40: TWSPLG | P40: 1348 | Q40: InTest
...

Sheet PN Dictionary
A1: PN | B1: Description
A2: CBL-C6-YL6FT-P | B2: Cable
A3: CBL-SRK-C6-YL7FT-P | B3: Cable
A4: SRK-01DTPF-33B1-01 | B4: Delta Power Shelf Left Input
A5: SRK-01DTPM-PMB1-01 | B5: Power Shelf Control Module
A6: SRK-01DTPW-5KB1-01 | B6: Power Supply Unit
A7: SRK-01KLRK-SWRAIL-05 | B7: Rail
A8: SRK-27LNAS-MKIT-A1C | B8: CC Mounting Kit
A9: SRK-48VLPG-GB200-EXT-01 | B9: Wooden Crate
A10: SRK-52SE-06-TW008 | B10: Rack Frame
A11: SSE-NVL72-CC | B11: Cable Cartridge
A12: SSE-NVL72SW-N5500 | B12: NVSwitch
... A27: ARS-121GL-NB3-LC1-TD004 | B27: GB300 L10

Sheet TD004 Summary
A1: SRS-GB300-M1-TD004 | B1: =TEXT(B2,"ddd") -> Mon | C1: =TEXT(C2,"ddd") -> Wed | D1: =TEXT(D2,"ddd") -> Thu | E1: =TEXT(E2,"ddd") -> Fri | F1: =TEXT(F2,"ddd") -> Sat | G1: =TEXT(G2,"ddd") -> Mon | H1: =TEXT(H2,"ddd") -> Tue | I1: =TEXT(I2,"ddd") -> Wed | ... P1: =TEXT(P2,"ddd") -> Mon | Q1: Sat-Sun | R1: =TEXT(R2,"ddd") -> Sun | S1: =TEXT(S2,"ddd") -> Mon | T1: =TEXT(T2,"ddd") -> Tue | U1: =TEXT(U2,"ddd") -> Wed | V1: =TEXT(V2,"ddd") -> Thu | W1: =TEXT(W2,"ddd") -> Fri | X1: =TEXT(X2,"ddd") -> Sat | Y1: =TEXT(Y2,"ddd") -> Sun | ... AB1: =TEXT(AB2,"ddd") -> Wed
B2: 46104 | C2: 46106 | D2: 46107 | E2: 46108 | F2: 46109 | G2: 46111 | H2: 46112 | I2: 46113 | J2: 46114 | K2: 46115 | L2: 46119 | M2: 46120 | N2: 46121 | O2: 46122 | P2: 46125 | Q2: 46123 | R2: 46124 | S2: 46125 | T2: 46126 | U2: 46127 | V2: 46128 | W2: 46129 | X2: 46130 | Y2: 46131 | Z2: 46132 | AA2: 46133 | AB2: 46134
A3: New Input Q'ty | B3: 1 | C3: 6 | D3: 0 | E3: 0 | F3: 0 | G3: 0 | H3: 0 | I3: 0 | J3: 0 | K3: 0 | L3: 1 | M3: 0 | N3: 0 | O3: 0 | P3: 0
A4: Pass Q'ty | B4: 0 | C4: 1 | D4: 0 | E4: 0 | F4: 5 | G4: 0 | H4: 0 | I4: 1 | J4: 0 | K4: 0 | L4: 0 | M4: 0 | N4: 0 | O4: 0 | P4: 1
A5: Running Q'ty | B5: 0 | C5: 0 | D5: 0 | E5: 0 | F5: 0 | G5: 0 | H5: 0 | I5: =H6+I3-I4 -> 0 | J5: =I6+J3-J4 -> 0 | K5: =J6+K3-K4 -> 0 | L5: 0 | M5: 0 | N5: 0 | O5: 1 | P5: 0 | Q5: =P6+Q3-Q4 -> 0 | R5: =Q6+R3-R4 -> 0 | S5: =R6+S3-S4 -> 0 | T5: =S6+T3-T4 -> 0 | U5: =T6+U3-U4 -> 0 | V5: =U6+V3-V4 -> 0 | W5: =V6+W3-W4 -> 0 | X5: =W6+X3-X4 -> 0 | ... AB5: =AA6+AB3-AB4 -> 0
A6: Failed Q'ty | B6: 1 | C6: 6 | D6: 6 | E6: 6 | F6: 1 | G6: 0 | H6: 1 | I6: 0 | J6: 0 | K6: 0 | L6: 0 | M6: 0 | N6: 1 | O6: 0 | P6: 0
A7: Untested / Insufficient test Q'ty | B7: 0 | C7: 0 | D7: 0 | E7: 0 | F7: 0 | G7: 0 | H7: 0 | I7: 0 | J7: 0 | K7: 0 | L7: 0 | M7: 0 | N7: 0 | O7: 0 | P7: 0
A8: L11 Finished Goods CUMULATIVE | B8: 0 | C8: =B8+C4 -> 1 | D8: =C8+D4 -> 1 | E8: =D8+E4 -> 1 | F8: =E8+F4 -> 6 | G8: =F8+G4 -> 6 | H8: =G8+H4 -> 6 | I8: =H8+I4 -> 7 | J8: =I8+J4 -> 7 | ... AB8: =AA8+AB4 -> 8
A9: Yield Rate | B9: =IFERROR(B4/(B4+B6),"N/A") -> 0 | C9: =IFERROR(C4/(C4+C6),"N/A") -> 0.14285714 | D9: =IFERROR(D4/(D4+D6),"N/A") -> 0 | E9: =IFERROR(E4/(E4+E6),"N/A") -> 0 | F9: =IFERROR(F4/(F4+F6),"N/A") -> 0.83333333 | G9: =IFERROR(G4/(G4+G6),"N/A") -> N/A | H9: =IFERROR(H4/(H4+H6),"N/A") -> 0 | I9: =IFERROR(I4/(I4+I6),"N/A") -> 1 | ... AB9: =IFERROR(AB4/(AB4+AB6),"N/A") -> N/A

Sheet FG001 Summary
B1: =TEXT(B2,"ddd") -> Sat | C1: =TEXT(C2,"ddd") -> Mon | D1: =TEXT(D2,"ddd") -> Tue | E1: =TEXT(E2,"ddd") -> Wed | F1: =TEXT(F2,"ddd") -> Thu | G1: =TEXT(G2,"ddd") -> Fri | H1: =TEXT(H2,"ddd") -> Sat | I1: =TEXT(I2,"ddd") -> Mon | ... AP1: =TEXT(AP2,"ddd") -> Sun | AQ1: Sat-Sun | AR1: =TEXT(AR2,"ddd") -> Tue | AS1: =TEXT(AS2,"ddd") -> Wed | AT1: =TEXT(AT2,"ddd") -> Thu | AU1: =TEXT(AU2,"ddd") -> Fri | AV1: =TEXT(AV2,"ddd") -> Sat | AW1: =TEXT(AW2,"ddd") -> Sun | AX1: =TEXT(AX2,"ddd") -> Mon | AY1: =TEXT(AY2,"ddd") -> Tue | ... BB1: =TEXT(BB2,"ddd") -> Fri
B2: 46046 | C2: 46048 | D2: 46049 | E2: 46050 | F2: 46051 | G2: 46052 | H2: 46053 | I2: 46055 | J2: 46056 | K2: 46057 | L2: 46058 | M2: 46059 | N2: 46060 | O2: 46062 | P2: 46063 | Q2: 46064 | R2: 46065 | S2: 46066 | T2: 46067 | U2: 46072 | V2: 46073 | W2: 46074 | X2: 46076 | Y2: 46077 | Z2: 46078 | AA2: 46079 | AB2: 46080 | AC2: 46081 | AD2: 46083 | AE2: 46084 | AF2: 46085 | AG2: 46086 | AH2: 46087 | AI2: 46088 | AJ2: 46090 | AK2: 46091 | AL2: 46092 | AM2: 46093 | AN2: 46094 | AO2: 46095 | AP2: 46096 | AQ2: 46097 | AR2: 46098 | AS2: 46099 | AT2: 46100 | AU2: 46101 | AV2: 46102 | AW2: 46103 | AX2: 46104 | AY2: 46105 | AZ2: 46106 | BA2: 46107 | BB2: 46108
A3: New Input Q'ty | B3: 2 | C3: 12 | D3: 8 | E3: 8 | F3: 3 | G3: 16 | H3: 21 | I3: 8 | J3: 16 | K3: 14 | L3: 15 | M3: 16 | N3: 11 | O3: 8 | P3: 10 | Q3: 10 | R3: 7 | S3: 11 | T3: 12 | U3: 0 | V3: 3 | W3: 5 | X3: 1 | Y3: 13 | Z3: 10 | AA3: 3 | AB3: 5 | AC3: 1 | AD3: 0 | AE3: 2 | AF3: 0 | AG3: 2 | AH3: 2 | AI3: 1 | AJ3: 0 | AK3: 0
A4: Pass Q'ty | B4: 0 | C4: 0 | D4: 6 | E4: 5 | F4: 8 | G4: 9 | H4: 14 | I4: 13 | J4: 10 | K4: 8 | L4: 15 | M4: 15 | N4: 13 | O4: 10 | P4: 14 | Q4: 19 | R4: 8 | S4: 18 | T4: 7 | U4: 4 | V4: 4 | W4: 2 | X4: 6 | Y4: 4 | Z4: 8 | AA4: 11 | AB4: 5 | AC4: 6 | AD4: 1 | AE4: 1 | AF4: 2 | AG4: 2 | AH4: 4 | AI4: 1 | AJ4: 3 | AK4: 0
A5: Running Q'ty | B5: 0 | C5: 0 | D5: 0 | E5: 0 | F5: 0 | G5: 0 | H5: 0 | I5: 0 | J5: 0 | K5: 0 | L5: 0 | M5: 0 | N5: 0 | O5: 0 | P5: 0 | Q5: 0 | R5: 0 | S5: 0 | T5: 0 | U5: 0 | V5: 0 | W5: 0 | X5: 0 | Y5: 0 | Z5: 0 | AA5: 0 | AB5: 0 | AC5: 0 | AD5: 0 | AE5: 0 | AF5: 0 | AG5: 0 | AH5: 0 | AI5: =AH6+AI3-AI4 -> 3 | AJ5: 0 | AK5: =AJ6+AK3-AK4 -> 0 | AL5: =AK6+AL3-AL4 -> 0 | AM5: =AL6+AM3-AM4 -> 0 | AN5: =AM6+AN3-AN4 -> 0 | AO5: =AN6+AO3-AO4 -> 0 | AP5: =AO6+AP3-AP4 -> 0 | AQ5: =AP6+AQ3-AQ4 -> 0 | AR5: =AQ6+AR3-AR4 -> 0 | ... BB5: =BA6+BB3-BB4 -> 0
A6: Failed Q'ty | B6: 0 | C6: 0 | D6: 16 | E6: 19 | F6: 14 | G6: 21 | H6: 7 | I6: 23 | J6: 29 | K6: 35 | L6: 35 | M6: 36 | N6: 34 | O6: 32 | P6: 28 | Q6: 19 | R6: 18 | S6: 11 | T6: 16 | U6: 12 | V6: 11 | W6: 14 | X6: 9 | Y6: 18 | Z6: 20 | AA6: 12 | AB6: 12 | AC6: 7 | AD6: 6 | AE6: 7 | AF6: 5 | AG6: 5 | AH6: 3 | AI6: 3 | AJ6: 0 | AK6: 0
A7: L11 Finished Goods CUMULATIVE | B7: 0 | C7: =B7+C4 -> 0 | D7: =C7+D4 -> 6 | E7: =D7+E4 -> 11 | F7: =E7+F4 -> 19 | G7: =F7+G4 -> 28 | H7: =G7+H4 -> 42 | I7: =H7+I4 -> 55 | J7: =I7+J4 -> 65 | ... BB7: =BA7+BB4 -> 256
A8: Yield Rate | B8: =IFERROR(B4/B3,"N/a") -> 0 | C8: =IFERROR(C4/C3,"N/a") -> 0 | D8: =IFERROR(D4/(D4+D6),"N/a") -> 0.27272727 | E8: =IFERROR(E4/(E4+E6),"N/a") -> 0.20833333 | F8: =IFERROR(F4/(F4+F6),"N/a") -> 0.36363636 | G8: =IFERROR(G4/(G4+G6),"N/a") -> 0.3 | H8: =IFERROR(H4/(H4+H6),"N/a") -> 0.66666667 | I8: =IFERROR(I4/(I4+I6),"N/a") -> 0.36111111 | J8: =IFERROR(J4/(J4+J6),"N/a") -> 0.25641026 | K8: =IFERROR(K4/(K4+K6),"N/a") -> 0.18604651 | ... T8: =IFERROR(T4/(T4+T6),"N/a") -> 0.30434783 | U8: =IFERROR(U4/(U4+U6),"N/A") -> 0.25 | V8: =IFERROR(V4/(V4+V6),"N/A") -> 0.26666667 | W8: =IFERROR(W4/(W4+W6),"N/A") -> 0.125 | X8: =IFERROR(X4/(X4+X6),"N/A") -> 0.4 | Y8: =IFERROR(Y4/(Y4+Y6),"N/A") -> 0.18181818 | Z8: =IFERROR(Z4/(Z4+Z6),"N/A") -> 0.28571429 | AA8: =IFERROR(AA4/(AA4+AA6),"N/A") -> 0.47826087 | AB8: =IFERROR(AB4/(AB4+AB6),"N/A") -> 0.29411765 | ... BB8: =IFERROR(BB4/(BB4+BB6),"N/A") -> N/A

Sheet MA023 Summary 
B1: =TEXT(B2,"ddd") -> Thu | C1: =TEXT(C2,"ddd") -> Fri | D1: =TEXT(D2,"ddd") -> Sat | E1: =TEXT(E2,"ddd") -> Sun | F1: =TEXT(F2,"ddd") -> Mon | G1: =TEXT(G2,"ddd") -> Tue | H1: =TEXT(H2,"ddd") -> Wed | I1: =TEXT(I2,"ddd") -> Thu | ... AE1: =TEXT(AE2,"ddd") -> Fri | AF1: Sat-Sun | AG1: =TEXT(AG2,"ddd") -> Mon | AH1: =TEXT(AH2,"ddd") -> Tue | AI1: =TEXT(AI2,"ddd") -> Wed | AJ1: =TEXT(AJ2,"ddd") -> Thu | AK1: =TEXT(AK2,"ddd") -> Fri | AL1: =TEXT(AL2,"ddd") -> Sat | AM1: =TEXT(AM2,"ddd") -> Sun | AN1: =TEXT(AN2,"ddd") -> Mon | ... AR1: =TEXT(AR2,"ddd") -> Fri | AS1: Sat-Sun | AT1: =TEXT(AT2,"ddd") -> Mon | AU1: =TEXT(AU2,"ddd") -> Tue | AV1: =TEXT(AV2,"ddd") -> Wed | AW1: =TEXT(AW2,"ddd") -> Thu | AX1: =TEXT(AX2,"ddd") -> Fri | AY1: =TEXT(AY2,"ddd") -> Sat | AZ1: =TEXT(AZ2,"ddd") -> Mon | BA1: =TEXT(BA2,"ddd") -> Tue | ... BD1: =TEXT(BD2,"ddd") -> Fri
B2: 45988 | C2: 45989 | D2: 45990 | E2: 45991 | F2: 45992 | G2: 45993 | H2: 45994 | I2: 45995 | J2: 45996 | K2: 45997 | L2: 45998 | M2: 45999 | N2: 46000 | O2: 46001 | P2: 46002 | Q2: 46003 | R2: 46004 | S2: 46005 | T2: 46006 | U2: 46007 | V2: 46008 | W2: 46009 | X2: 46010 | Y2: 46011 | Z2: 46012 | AA2: 46013 | AB2: 46014 | AC2: 46015 | AD2: 46016 | AE2: 46017 | AF2: 12/27-12/28 | AG2: 46020 | AH2: 46021 | AI2: 46022 | AJ2: 46023 | AK2: 46024 | AL2: 46025 | AM2: 46026 | AN2: 46027 | AO2: 46028 | AP2: 46029 | AQ2: 46030 | AR2: 46031 | AS2: 2026/1/10-1/11 | AT2: 46034 | AU2: 46035 | AV2: 46036 | AW2: 46037 | AX2: 46038 | AY2: 46039 | AZ2: 46041 | BA2: 46042 | BB2: 46043 | BC2: 46044 | BD2: 46045
A3: Input Q'ty | B3: 2 | C3: 0 | D3: 0 | E3: 0 | F3: 0 | G3: 0 | H3: 0 | I3: 5 | J3: 11 | K3: 10 | L3: 3 | M3: 12 | N3: 12 | O3: 6 | P3: 9 | Q3: 5 | R3: 0 | S3: 0 | T3: 0 | U3: 0 | V3: 5 | W3: 0 | X3: 0 | Y3: 0 | Z3: 0 | AA3: 0 | AB3: 0 | AC3: 0 | AD3: 0 | AE3: 0 | AF3: 5 | AG3: 8 | AH3: 13 | AI3: 10 | AJ3: 6 | AK3: 0 | AL3: 1 | AM3: 0 | AN3: 0 | AO3: 0 | AP3: 2 | AQ3: 9 | AR3: 8 | AS3: 8 | AT3: 11 | AU3: 9 | AV3: 6 | AW3: 3 | AX3: 2 | AY3: 3 | AZ3: 2 | BA3: 0 | BB3: 2 | BC3: 2 | BD3: 2
A4: Pass Q'ty | B4: 0 | C4: 0 | D4: 0 | E4: 0 | F4: 0 | G4: 1 | H4: 0 | I4: 0 | J4: 1 | K4: 1 | L4: 7 | M4: 10 | N4: 5 | O4: 14 | P4: 14 | Q4: 9 | R4: 6 | S4: 3 | T4: 2 | U4: 1 | V4: 1 | W4: 0 | X4: 4 | Y4: 0 | Z4: 1 | AA4: 0 | AB4: 0 | AC4: 0 | AD4: 0 | AE4: 0 | AF4: 0 | AG4: 4 | AH4: 9 | AI4: 8 | AJ4: 7 | AK4: 10 | AL4: 3 | AM4: 0 | AN4: 0 | AO4: 1 | AP4: 1 | AQ4: 2 | AR4: 5 | AS4: 11 | AT4: 10 | AU4: 8 | AV4: 12 | AW4: 5 | AX4: 1 | AY4: 4 | AZ4: 3 | BA4: 1 | BB4: 1 | BC4: 2 | BD4: 2
A5: Running Q'ty | B5: 0 | C5: 0 | D5: 0 | E5: 0 | F5: 0 | G5: 0 | H5: 0 | I5: 0 | J5: 0 | K5: 0 | L5: 0 | M5: 0 | N5: 0 | O5: 0 | P5: 0 | Q5: 0 | R5: 0 | S5: 0 | T5: 0 | U5: 0 | V5: 0 | W5: 0 | X5: 0 | Y5: 0 | Z5: 0 | AA5: 0 | AB5: 0 | AC5: 0 | AD5: 0 | AE5: 0 | AF5: 0 | AG5: 0 | AH5: 0 | AI5: 0 | AJ5: 0 | AK5: 0 | AL5: 0 | AM5: 0 | AN5: 0 | AO5: 0 | AP5: 0 | AQ5: 0 | AR5: 0 | AS5: 0 | AT5: 0 | AU5: 0 | AV5: 0 | AW5: 0 | AX5: 0 | AY5: 0 | AZ5: 0 | BA5: 0 | BB5: 0 | BC5: 2 | BD5: 0
A6: Failed Q'ty | B6: 2 | C6: 2 | D6: 2 | E6: 2 | F6: 2 | G6: 1 | H6: 1 | I6: 6 | J6: 16 | K6: 25 | L6: 21 | M6: 23 | N6: 30 | O6: 22 | P6: 17 | Q6: 13 | R6: 7 | S6: 4 | T6: 2 | U6: 1 | V6: 5 | W6: 5 | X6: 1 | Y6: 1 | Z6: 0 | AA6: 0 | AB6: 0 | AC6: 0 | AD6: 0 | AE6: 0 | AF6: 5 | AG6: 9 | AH6: 13 | AI6: 15 | AJ6: 14 | AK6: 4 | AL6: 2 | AM6: 2 | AN6: 2 | AO6: 1 | AP6: 2 | AQ6: 9 | AR6: 12 | AS6: 9 | AT6: 10 | AU6: 11 | AV6: 5 | AW6: 3 | AX6: 4 | AY6: 3 | AZ6: 2 | BA6: 1 | BB6: 2 | BC6: 2 | BD6: 0
A7: L11 Finished Goods CUMULATIVE | B7: 0 | C7: 0 | D7: 0 | E7: 0 | F7: 0 | G7: =F7+G4 -> 1 | H7: =G7+H4 -> 1 | I7: =H7+I4 -> 1 | J7: =I7+J4 -> 2 | K7: =J7+K4 -> 3 | L7: =K7+L4 -> 10 | M7: =L7+M4 -> 20 | N7: =M7+N4 -> 25 | ... AS7: =AR7+AS4 -> 141 | AT7: 151 | AU7: 159 | AV7: 171 | AW7: 176 | AX7: 177 | AY7: 181 | AZ7: 184 | BA7: 185 | BB7: =BA7+BB4 -> 186 | BC7: =BB7+BC4 -> 188 | BD7: =BC7+BD4 -> 190
A8: Yield Rate | B8: =IFERROR(B4/B3,"N/a") -> 0 | C8: =IFERROR(C4/(C4+C6),"N/a") -> 0 | D8: =IFERROR(D4/(D4+D6),"N/a") -> 0 | E8: =IFERROR(E4/(E4+E6),"N/a") -> 0 | F8: =IFERROR(F4/(F4+F6),"N/a") -> 0 | G8: =IFERROR(G4/(G4+G6),"N/a") -> 0.5 | H8: =IFERROR(H4/(H4+H6),"N/a") -> 0 | I8: =IFERROR(I4/(I4+I6),"N/a") -> 0 | J8: =IFERROR(J4/(J4+J6),"N/a") -> 0.058823529 | ... BD8: =IFERROR(BD4/(BD4+BD6),"N/a") -> 1

Sheet xAI_TW008 Summary
B1: =TEXT(B2,"ddd") -> Tue | C1: =TEXT(C2,"ddd") -> Wed | D1: =TEXT(D2,"ddd") -> Thu | E1: =TEXT(E2,"ddd") -> Fri | F1: Sat & Sun | G1: =TEXT(G2,"ddd") -> Mon | H1: =TEXT(H2,"ddd") -> Tue | I1: =TEXT(I2,"ddd") -> Wed | J1: =TEXT(J2,"ddd") -> Thu | K1: =TEXT(K2,"ddd") -> Fri | L1: =TEXT(L2,"ddd") -> Sat | M1: =TEXT(M2,"ddd") -> Sun | N1: =TEXT(N2,"ddd") -> Mon | ... R1: =TEXT(R2,"ddd") -> Fri | S1: Sat & Sun | T1: =TEXT(T2,"ddd") -> Mon | U1: =TEXT(U2,"ddd") -> Tue | V1: =TEXT(V2,"ddd") -> Wed | W1: =TEXT(W2,"ddd") -> Thu | X1: =TEXT(X2,"ddd") -> Fri | Y1: =TEXT(Y2,"ddd") -> Sat | Z1: =TEXT(Z2,"ddd") -> Sun | AA1: =TEXT(AA2,"ddd") -> Mon | ... BP1: =TEXT(BP2,"ddd") -> Mon
B2: 45958 | C2: 45959 | D2: 45960 | E2: 45961 | F2: 11/1-11/2 | G2: 45964 | H2: 45965 | I2: 45966 | J2: 45967 | K2: 45968 | L2: 45969 | M2: 45970 | N2: 45971 | O2: 45972 | P2: 45973 | Q2: 45974 | R2: 45975 | S2: 11/15-11/16 | T2: 45978 | U2: 45979 | V2: 45980 | W2: 45981 | X2: 45982 | Y2: 45983 | Z2: 45984 | AA2: 45985 | AB2: 45986 | AC2: 45987 | AD2: 45988 | AE2: 45989 | AF2: 45990 | AG2: 45991 | AH2: 45992 | AI2: 45993 | AJ2: 45994 | AK2: 45995 | AL2: 45996 | AM2: 45997 | AN2: 45998 | AO2: 45999 | AP2: 46000 | AQ2: 46001 | AR2: 46002 | AS2: 46003 | AT2: 46004 | AU2: 46005 | AV2: 46006 | AW2: 46007 | AX2: 46008 | AY2: 46009 | AZ2: 46010 | BA2: 46011 | BB2: 46012 | BC2: 46013 | BD2: 46014 | BE2: 46015 | BF2: 46016 | BG2: 46017 | BH2: 46018 | BI2: 46020 | BJ2: 46021 | BK2: 46022 | BL2: 46023 | BM2: 46024 | BN2: 46025 | BO2: 46026 | BP2: 46027
A3: Input Q'ty | B3: =SUM(B4:B6) -> 2 | C3: 0 | D3: 0 | E3: =SUM(E4:E6) -> 0 | F3: 14 | G3: 1 | H3: 1 | I3: 2 | J3: 3 | K3: 9 | L3: 8 | M3: 0 | N3: 3 | O3: 3 | P3: 5 | Q3: 11 | R3: 12 | S3: 10 | T3: 14 | U3: 10 | V3: 16 | W3: 20 | X3: 17 | Y3: 7 | Z3: 4 | AA3: 17 | AB3: 15 | AC3: 15 | AD3: 11 | AE3: 11 | AF3: 15 | AG3: 13 | AH3: 15 | AI3: 16 | AJ3: 20 | AK3: 10 | AL3: 0 | AM3: 0 | AN3: 8 | AO3: 0 | AP3: 2 | AQ3: 10 | AR3: 10 | AS3: 15 | AT3: 11 | AU3: 16 | AV3: 16 | AW3: 18 | AX3: 14 | AY3: 17 | AZ3: 18 | BA3: 18 | BB3: 6 | BC3: 16 | BD3: 18 | BE3: 18 | BF3: 12 | BG3: 3 | BH3: 5 | BI3: 7 | BJ3: 3 | BK3: 2 | BL3: 1 | BM3: 2 | BN3: 3 | BO3: 1 | BP3: 0
A4: Pass Q'ty | B4: 0 | C4: 0 | D4: 2 | E4: 0 | F4: 0 | G4: 6 | H4: 2 | I4: 5 | J4: 3 | K4: 4 | L4: 2 | M4: 4 | N4: 7 | O4: 5 | P4: 2 | Q4: 8 | R4: 9 | S4: 10 | T4: 8 | U4: 15 | V4: 7 | W4: 6 | X4: 12 | Y4: 17 | Z4: 13 | AA4: 9 | AB4: 16 | AC4: 15 | AD4: 15 | AE4: 14 | AF4: 14 | AG4: 11 | AH4: 13 | AI4: 14 | AJ4: 15 | AK4: 15 | AL4: 14 | AM4: 11 | AN4: 4 | AO4: 4 | AP4: 5 | AQ4: 1 | AR4: 1 | AS4: 7 | AT4: 10 | AU4: 12 | AV4: 13 | AW4: 16 | AX4: 16 | AY4: 18 | AZ4: 14 | BA4: 16 | BB4: 14 | BC4: 17 | BD4: 17 | BE4: 17 | BF4: 15 | BG4: 15 | BH4: 10 | BI4: 11 | BJ4: 5 | BK4: 3 | BL4: 5 | BM4: 2 | BN4: 4 | BO4: 1 | BP4: 4
A5: Running Q'ty | B5: 0 | C5: 0 | D5: 0 | E5: 0 | F5: 0 | G5: 0 | H5: 0 | I5: 0 | J5: 0 | K5: 0 | L5: 0 | M5: 0 | N5: 0 | O5: 0 | P5: 0 | Q5: 0 | R5: 0 | S5: 0 | T5: 0 | U5: 0 | V5: 0 | W5: 0 | X5: 0 | Y5: 0 | Z5: 0 | AA5: 0 | AB5: 0 | AC5: 0 | AD5: 0 | AE5: 0 | AF5: 0 | AG5: 0 | AH5: 0 | AI5: 0 | AJ5: 0 | AK5: 0 | AL5: 0 | AM5: 0 | AN5: 0 | AO5: 0 | AP5: 0 | AQ5: 0 | AR5: 0 | AS5: 0 | AT5: 0 | AU5: 0 | AV5: 0 | AW5: 0 | AX5: 0 | AY5: 0 | AZ5: 0 | BA5: 0 | BB5: 0 | BC5: 0 | BD5: 0 | BE5: 0 | BF5: 0 | BG5: 0 | BH5: 0 | BI5: 0 | BJ5: 0 | BK5: 0 | BL5: 0 | BM5: 0 | BN5: 4 | BO5: 0 | BP5: 0
A6: Failed Q'ty | B6: 2 | C6: 2 | D6: 0 | E6: 0 | F6: 14 | G6: 9 | H6: 8 | I6: 5 | J6: 5 | K6: 10 | L6: 16 | M6: 12 | N6: 8 | O6: 6 | P6: 9 | Q6: 12 | R6: 15 | S6: 15 | T6: 21 | U6: 16 | V6: 25 | W6: 39 | X6: 44 | Y6: 34 | Z6: 25 | AA6: 33 | AB6: 32 | AC6: 32 | AD6: 28 | AE6: 25 | AF6: 26 | AG6: 28 | AH6: 30 | AI6: 32 | AJ6: 37 | AK6: 32 | AL6: 18 | AM6: 7 | AN6: 11 | AO6: 7 | AP6: 4 | AQ6: 13 | AR6: 22 | AS6: 30 | AT6: 31 | AU6: 35 | AV6: 38 | AW6: 40 | AX6: 38 | AY6: 37 | AZ6: 41 | BA6: 43 | BB6: 35 | BC6: 34 | BD6: 35 | BE6: 36 | BF6: 33 | BG6: 21 | BH6: 16 | BI6: 12 | BJ6: 10 | BK6: 9 | BL6: 5 | BM6: 5 | BN6: 4 | BO6: 4 | BP6: 0
A7: L11 Finished Goods CUMULATIVE | B7: 0 | C7: 0 | D7: 2 | E7: 0 | F7: 0 | G7: 8 | H7: 10 | I7: 15 | J7: 18 | K7: 22 | L7: 24 | M7: 28 | N7: 35 | O7: 40 | P7: 42 | Q7: 50 | R7: 59 | S7: 69 | T7: 77 | U7: 92 | V7: 99 | W7: =V7+W4 -> 105 | X7: =W7+X4 -> 117 | Y7: =X7+Y4 -> 134 | Z7: =Y7+Z4 -> 147 | AA7: =Z7+AA4 -> 156 | AB7: =AA7+AB4 -> 172 | AC7: =AB7+AC4 -> 187 | AD7: =AC7+AD4 -> 202 | ... BP7: =BO7+BP4 -> 600
A8: Yield Rate | B8: =IFERROR(B4/B3,"N/a") -> 0 | C8: =IFERROR(C4/(C4+C6),"N/a") -> 0 | D8: =IFERROR(D4/(D4+D6),"N/a") -> 1 | E8: =IFERROR(E4/(E4+E6),"N/a") -> N/a | F8: =IFERROR(F4/(F4+F6),"N/a") -> 0 | G8: =IFERROR(G4/(G4+G6),"N/a") -> 0.4 | H8: =IFERROR(H4/(H4+H6),"N/a") -> 0.2 | I8: =IFERROR(I4/(I4+I6),"N/a") -> 0.5 | J8: =IFERROR(J4/(J4+J6),"N/a") -> 0.375 | ... BP8: =IFERROR(BP4/(BP4+BP6),"N/a") -> 1

Sheet GVMetadata
A2: GVData | B2: ew0KICAiZG9jSUQiOiAiZDAxYTczOWQtZDkyYS00OWI4LTliOGUtZTgzNWQ2MTczYzk2Ig0KfQ==
A3: GVData0 | B3: (end)
